[2018-10-09 05:23:25,824] ERROR task_13: cannot get frame #0
Traceback (most recent call last):
  File "/home/yilinma/Documents/LabellingTool/cvat/cvat/apps/engine/views.py", line 120, in get_frame
    return sendfile(request, path)
  File "/home/yilinma/Documents/LabellingTool/cvat/cvat/venv_labelling_tool/lib/python3.6/site-packages/sendfile/__init__.py", line 59, in sendfile
    raise Http404('"%s" does not exist' % filename)
django.http.response.Http404: "/home/yilinma/Documents/LabellingTool/cvat/data/13/data/0/0/0.jpg" does not exist
[2018-10-09 05:23:53,082] ERROR task_13: cannot get frame #0
Traceback (most recent call last):
  File "/home/yilinma/Documents/LabellingTool/cvat/cvat/apps/engine/views.py", line 120, in get_frame
    return sendfile(request, path)
  File "/home/yilinma/Documents/LabellingTool/cvat/cvat/venv_labelling_tool/lib/python3.6/site-packages/sendfile/__init__.py", line 59, in sendfile
    raise Http404('"%s" does not exist' % filename)
django.http.response.Http404: "/home/yilinma/Documents/LabellingTool/cvat/data/13/data/0/0/0.jpg" does not exist
[2018-10-09 05:27:03,657] ERROR task_13: cannot get frame #0
Traceback (most recent call last):
  File "/home/yilinma/Documents/LabellingTool/cvat/cvat/apps/engine/views.py", line 120, in get_frame
    return sendfile(request, path)
  File "/home/yilinma/Documents/LabellingTool/cvat/cvat/venv_labelling_tool/lib/python3.6/site-packages/sendfile/__init__.py", line 59, in sendfile
    raise Http404('"%s" does not exist' % filename)
django.http.response.Http404: "/home/yilinma/Documents/LabellingTool/cvat/data/13/data/0/0/0.jpg" does not exist
[2018-10-09 05:29:02,735] ERROR task_13: cannot get frame #0
Traceback (most recent call last):
  File "/home/yilinma/Documents/LabellingTool/cvat/cvat/apps/engine/views.py", line 120, in get_frame
    return sendfile(request, path)
  File "/home/yilinma/Documents/LabellingTool/cvat/cvat/venv_labelling_tool/lib/python3.6/site-packages/sendfile/__init__.py", line 59, in sendfile
    raise Http404('"%s" does not exist' % filename)
django.http.response.Http404: "/home/yilinma/Documents/LabellingTool/cvat/data/13/data/0/0/0.jpg" does not exist
[2018-10-09 05:29:50,772] ERROR task_13: cannot get frame #0
Traceback (most recent call last):
  File "/home/yilinma/Documents/LabellingTool/cvat/cvat/apps/engine/views.py", line 120, in get_frame
    return sendfile(request, path)
  File "/home/yilinma/Documents/LabellingTool/cvat/cvat/venv_labelling_tool/lib/python3.6/site-packages/sendfile/__init__.py", line 59, in sendfile
    raise Http404('"%s" does not exist' % filename)
django.http.response.Http404: "/home/yilinma/Documents/LabellingTool/cvat/data/13/data/0/0/0.jpg" does not exist
[2018-10-09 06:03:08,383] ERROR task_13: cannot get frame #0
Traceback (most recent call last):
  File "/home/yilinma/Documents/LabellingTool/cvat/cvat/apps/engine/views.py", line 120, in get_frame
    return sendfile(request, path)
  File "/home/yilinma/Documents/LabellingTool/cvat/cvat/venv_labelling_tool/lib/python3.6/site-packages/sendfile/__init__.py", line 59, in sendfile
    raise Http404('"%s" does not exist' % filename)
django.http.response.Http404: "/home/yilinma/Documents/LabellingTool/cvat/data/13/data/0/0/0.jpg" does not exist
