[2018-10-09 12:24:45,640] ERROR task_20: cannot get frame #0
Traceback (most recent call last):
  File "/home/yilinma/Documents/LabellingTool/cvat/cvat/apps/engine/views.py", line 123, in get_frame
    return sendfile(request, path)
  File "/home/yilinma/Documents/LabellingTool/cvat/cvat/venv_labelling_tool/lib/python3.6/site-packages/sendfile/__init__.py", line 59, in sendfile
    raise Http404('"%s" does not exist' % filename)
django.http.response.Http404: "/home/yilinma/Documents/LabellingTool/cvat/data/20/data/0/0/0.jpg" does not exist
[2018-10-10 04:40:41,760] ERROR task_20: cannot get frame #0
Traceback (most recent call last):
  File "/home/yilinma/Documents/LabellingTool/cvat/cvat/apps/engine/views.py", line 140, in get_frame
    return sendfile(request, path)
  File "/home/yilinma/Documents/LabellingTool/cvat/cvat/venv_labelling_tool/lib/python3.6/site-packages/sendfile/__init__.py", line 59, in sendfile
    raise Http404('"%s" does not exist' % filename)
django.http.response.Http404: "/home/yilinma/Documents/LabellingTool/cvat/data/20/data/0/0/0.jpg" does not exist
[2018-10-10 04:42:34,524] ERROR task_20: cannot get frame #0
Traceback (most recent call last):
  File "/home/yilinma/Documents/LabellingTool/cvat/cvat/apps/engine/views.py", line 140, in get_frame
    return sendfile(request, path)
  File "/home/yilinma/Documents/LabellingTool/cvat/cvat/venv_labelling_tool/lib/python3.6/site-packages/sendfile/__init__.py", line 59, in sendfile
    raise Http404('"%s" does not exist' % filename)
django.http.response.Http404: "/home/yilinma/Documents/LabellingTool/cvat/data/20/data/0/0/0.jpg" does not exist
[2018-10-10 04:49:22,257] ERROR task_20: cannot get frame #0
Traceback (most recent call last):
  File "/home/yilinma/Documents/LabellingTool/cvat/cvat/apps/engine/views.py", line 140, in get_frame
    return sendfile(request, path)
  File "/home/yilinma/Documents/LabellingTool/cvat/cvat/venv_labelling_tool/lib/python3.6/site-packages/sendfile/__init__.py", line 59, in sendfile
    raise Http404('"%s" does not exist' % filename)
django.http.response.Http404: "/home/yilinma/Documents/LabellingTool/cvat/data/20/data/0/0/0.jpg" does not exist
[2018-10-10 05:24:23,079] ERROR task_20: cannot get frame #0
Traceback (most recent call last):
  File "/home/yilinma/Documents/LabellingTool/cvat/cvat/apps/engine/views.py", line 140, in get_frame
    return sendfile(request, path)
  File "/home/yilinma/Documents/LabellingTool/cvat/cvat/venv_labelling_tool/lib/python3.6/site-packages/sendfile/__init__.py", line 59, in sendfile
    raise Http404('"%s" does not exist' % filename)
django.http.response.Http404: "/home/yilinma/Documents/LabellingTool/cvat/data/20/data/0/0/0.jpg" does not exist
